Workbook

Sheet Calculadora
A1: CALCULADORA DE INGRESOS
A2: Celdas amarillas con texto azul = datos editables. Todo lo demás se calcula solo.
A4: 1. DATOS (EDITABLES) | B4: Valor | C4: Nota
A5: Sueldo básico mensual | B5: 2350 | C5: Ejemplo dado por el usuario. Cámbialo por tu sueldo.
A6: Horas legales por semana | B6: 48 | C6: Jornada ordinaria semanal.
A7: Horas extra por semana | B7: 9 | C7: 57 h trabajadas - 48 h legales = 9 h extra.
A8: Recargo por hora extra | B8: 0.25 | C8: 25% sobre el valor de la hora normal.
A9: Descuento AFP | B9: 0.12 | C9: Porcentaje aplicado sobre el ingreso bruto.
A10: Días laborables por semana | B10: 6 | C10: 48 h / 6 días = 8 h por día.
A11: Días base del mes (cálculo valor hora) | B11: 30 | C11: Convención usual: sueldo / 30 días / horas diarias.
A12: Semanas por mes | B12: =52/12 -> 4.3333333 | C12: 52 semanas / 12 meses = 4.3333. Puedes poner 4 si te pagan por 4 semanas.
A13: Otros ingresos mensuales (bonos, movilidad) | B13: 0 | C13: Opcional. Se suman al bruto y pagan AFP.
A14: Otros descuentos mensuales | B14: 0 | C14: Opcional (préstamos, adelantos, etc.). Se restan del neto.
A16: 2. VALOR DE LA HORA | B16: Valor | C16: Nota
A17: Horas por día (jornada) | B17: =B6/B10 -> 8 | C17: Horas legales semanales / días laborables.
A18: Pago diario base | B18: =B5/B11 -> 78.333333 | C18: Sueldo / días base del mes.
A19: Pago por hora normal | B19: =IFERROR(B18/B17,0) -> 9.7916667 | C19: Pago diario / horas por día.
A20: Pago por hora extra | B20: =B19*(1+B8) -> 12.239583 | C20: Hora normal × (1 + recargo).
A21: Ganancia adicional por cada hora extra | B21: =B20-B19 -> 2.4479167 | C21: Lo que suma el recargo por hora.
A23: 3. RESULTADO SEMANAL | B23: Valor | C23: Nota
A24: Horas totales trabajadas por semana | B24: =B6+B7 -> 57 | C24: Legales + extra.
A25: Pago semanal base | B25: =B5/B12 -> 542.30769 | C25: Sueldo mensual / semanas por mes.
A26: Pago semanal por horas extra | B26: =B7*B20 -> 110.15625 | C26: Horas extra × pago por hora extra.
A27: Bruto semanal | B27: =B25+B26+B13/B12 -> 652.46394 | C27: Base + extras + otros ingresos prorrateados.
A28: AFP semanal | B28: =B27*B9 -> 78.295673
A29: Neto semanal | B29: =B27-B28-B14/B12 -> 574.16827 | C29: Bruto - AFP - otros descuentos prorrateados.
A31: 4. RESULTADO MENSUAL | B31: Valor | C31: Nota
A32: Sueldo básico | B32: =B5 -> 2350
A33: Horas extra en el mes | B33: =B7*B12 -> 39 | C33: Horas extra semanales × semanas por mes.
A34: Pago por horas extra (mes) | B34: =B33*B20 -> 477.34375
A35: Otros ingresos | B35: =B13 -> 0
A36: INGRESO BRUTO MENSUAL | B36: =B32+B34+B35 -> 2827.3438
A37: Descuento AFP | B37: =-B36*B9 -> -339.28125 | C37: Bruto × % AFP (se muestra en negativo).
A38: Otros descuentos | B38: =-B14 -> 0
A39: INGRESO NETO MENSUAL | B39: =B36+B37+B38 -> 2488.0625 | C39: Lo que recibes en mano.
A41: 5. OTROS RESULTADOS | B41: Valor | C41: Nota
A42: Neto por día (calendario, /30) | B42: =B39/B11 -> 82.935417 | C42: Neto mensual / días base.
A43: Neto por día trabajado | B43: =B39/(B10*B12) -> 95.694712 | C43: Neto mensual / días laborados en el mes.
A44: Neto por hora trabajada real | B44: =B39/(B24*B12) -> 10.073128 | C44: Neto mensual / todas las horas trabajadas (incluye extras).
A45: Bruto por hora trabajada real | B45: =B36/(B24*B12) -> 11.446736
...

Sheet Escenarios
A1: ¿CUÁNTO GANO SEGÚN LAS HORAS EXTRA?
A2: Usa los datos de la hoja Calculadora. Puedes cambiar las horas extra de la columna A (azul).
A4: Horas extra / semana | B4: Horas totales / semana | C4: Pago extra mensual | D4: Bruto mensual | E4: AFP mensual | F4: Neto mensual
A5: 0 | B5: =Calculadora!$B$6+A5 -> 48 | C5: =A5*Calculadora!$B$12*Calculadora!$B$20 -> 0 | D5: =Calculadora!$B$5+C5+Calculadora!$B$13 -> 2350 | E5: =-D5*Calculadora!$B$9 -> -282 | F5: =D5+E5-Calculadora!$B$14 -> 2068
A6: 1 | B6: =Calculadora!$B$6+A6 -> 49 | C6: =A6*Calculadora!$B$12*Calculadora!$B$20 -> 53.038194 | D6: =Calculadora!$B$5+C6+Calculadora!$B$13 -> 2403.0382 | E6: =-D6*Calculadora!$B$9 -> -288.36458 | F6: =D6+E6-Calculadora!$B$14 -> 2114.6736
A7: 2 | B7: =Calculadora!$B$6+A7 -> 50 | C7: =A7*Calculadora!$B$12*Calculadora!$B$20 -> 106.07639 | D7: =Calculadora!$B$5+C7+Calculadora!$B$13 -> 2456.0764 | E7: =-D7*Calculadora!$B$9 -> -294.72917 | F7: =D7+E7-Calculadora!$B$14 -> 2161.3472
A8: 3 | B8: =Calculadora!$B$6+A8 -> 51 | C8: =A8*Calculadora!$B$12*Calculadora!$B$20 -> 159.11458 | D8: =Calculadora!$B$5+C8+Calculadora!$B$13 -> 2509.1146 | E8: =-D8*Calculadora!$B$9 -> -301.09375 | F8: =D8+E8-Calculadora!$B$14 -> 2208.0208
A9: 4 | B9: =Calculadora!$B$6+A9 -> 52 | C9: =A9*Calculadora!$B$12*Calculadora!$B$20 -> 212.15278 | D9: =Calculadora!$B$5+C9+Calculadora!$B$13 -> 2562.1528 | E9: =-D9*Calculadora!$B$9 -> -307.45833 | F9: =D9+E9-Calculadora!$B$14 -> 2254.6944
A10: 5 | B10: =Calculadora!$B$6+A10 -> 53 | C10: =A10*Calculadora!$B$12*Calculadora!$B$20 -> 265.19097 | D10: =Calculadora!$B$5+C10+Calculadora!$B$13 -> 2615.191 | E10: =-D10*Calculadora!$B$9 -> -313.82292 | F10: =D10+E10-Calculadora!$B$14 -> 2301.3681
A11: 6 | B11: =Calculadora!$B$6+A11 -> 54 | C11: =A11*Calculadora!$B$12*Calculadora!$B$20 -> 318.22917 | D11: =Calculadora!$B$5+C11+Calculadora!$B$13 -> 2668.2292 | E11: =-D11*Calculadora!$B$9 -> -320.1875 | F11: =D11+E11-Calculadora!$B$14 -> 2348.0417
A12: 7 | B12: =Calculadora!$B$6+A12 -> 55 | C12: =A12*Calculadora!$B$12*Calculadora!$B$20 -> 371.26736 | D12: =Calculadora!$B$5+C12+Calculadora!$B$13 -> 2721.2674 | E12: =-D12*Calculadora!$B$9 -> -326.55208 | F12: =D12+E12-Calculadora!$B$14 -> 2394.7153
A13: 8 | B13: =Calculadora!$B$6+A13 -> 56 | C13: =A13*Calculadora!$B$12*Calculadora!$B$20 -> 424.30556 | D13: =Calculadora!$B$5+C13+Calculadora!$B$13 -> 2774.3056 | E13: =-D13*Calculadora!$B$9 -> -332.91667 | F13: =D13+E13-Calculadora!$B$14 -> 2441.3889
A14: 9 | B14: =Calculadora!$B$6+A14 -> 57 | C14: =A14*Calculadora!$B$12*Calculadora!$B$20 -> 477.34375 | D14: =Calculadora!$B$5+C14+Calculadora!$B$13 -> 2827.3438 | E14: =-D14*Calculadora!$B$9 -> -339.28125 | F14: =D14+E14-Calculadora!$B$14 -> 2488.0625
A15: 10 | B15: =Calculadora!$B$6+A15 -> 58 | C15: =A15*Calculadora!$B$12*Calculadora!$B$20 -> 530.38194 | D15: =Calculadora!$B$5+C15+Calculadora!$B$13 -> 2880.3819 | E15: =-D15*Calculadora!$B$9 -> -345.64583 | F15: =D15+E15-Calculadora!$B$14 -> 2534.7361
A16: 11 | B16: =Calculadora!$B$6+A16 -> 59 | C16: =A16*Calculadora!$B$12*Calculadora!$B$20 -> 583.42014 | D16: =Calculadora!$B$5+C16+Calculadora!$B$13 -> 2933.4201 | E16: =-D16*Calculadora!$B$9 -> -352.01042 | F16: =D16+E16-Calculadora!$B$14 -> 2581.4097
... A25: 20 | B25: =Calculadora!$B$6+A25 -> 68 | C25: =A25*Calculadora!$B$12*Calculadora!$B$20 -> 1060.7639 | D25: =Calculadora!$B$5+C25+Calculadora!$B$13 -> 3410.7639 | E25: =-D25*Calculadora!$B$9 -> -409.29167 | F25: =D25+E25-Calculadora!$B$14 -> 3001.4722
